<?xml version="1.0" encoding="UTF-8"?>
<robot xmlns:xacro="http://www.ros.org/wiki/xacro">
	<xacro:property name="wheelbase" value="$(arg wheel_base)" />
	<xacro:macro name="base" params="colour">
	
		<link name="base_link">
		   	<inertial>
				<origin xyz="-0.20 0.00163 0.07094" rpy="0 0 0" />
				<mass value="1.5" />
				<inertia ixx="0.0025" ixy="0.00013" ixz="0.00419" iyy="0.01593" iyz="0" izz="0.01605" />
				<gravity>1</gravity>
			</inertial>
			<visual>
				<origin  xyz="0 0 0" rpy="0 0 0" />
				<geometry> 
					<mesh filename="package://scouting_robot_description/meshes/body_front.dae" />
				</geometry> 
				<material name="${colour}" />
			</visual>
			<collision>
				<origin xyz="0 0 0" rpy="0 0 0" />
				<geometry> 
					<mesh filename="package://scouting_robot_description/meshes/body_front.dae" />	
				</geometry>		
			</collision>
		</link>


		<link name="back_link">
			<inertial>
				<origin xyz="0 -0.023 0.035" rpy="0 0 0" />
				<mass value="0.56" />
				<inertia ixx="0.000214" ixy="0" ixz="0" iyy="0.0015171" iyz="0" izz="0.001316" />
			</inertial>
			<visual>
				<origin xyz="0 0 0" rpy="0 0 0" />
				<geometry> 
					<mesh filename="package://scouting_robot_description/meshes/body_back.dae" />
				</geometry>
				<material name="${colour}"/>				
			</visual>
			<collision>
				<origin xyz="0 0 0" rpy="0 0 0"/>
				<geometry>
					<mesh filename="package://scouting_robot_description/meshes/body_back.dae" />
				</geometry>
			</collision>
		</link>
		
		<joint name="pivot_joint" type="revolute">
			<origin xyz="-${wheelbase} 0 0" rpy="0 0 0"/>
			<parent link="base_link"/>
			<child  link="back_link"/>		
			<axis xyz="1 0 0"/>
			<limit lower="-${M_PI*0.25}" upper="${M_PI*0.25}" effort="10" velocity="5"/>
		</joint>	

		<gazebo reference="base_link">
			<selfCollide>false</selfCollide>
		</gazebo>		
				
		<gazebo reference="back_link">
			<selfCollide>false</selfCollide>
		</gazebo>
	</xacro:macro>
</robot>
