<sdf version='1.6'>
  <world name='default'>
    <light name='sun' type='directional'>
      <cast_shadows>1</cast_shadows>
      <pose frame=''>0 0 10 0 -0 0</pose>
      <diffuse>0.8 0.8 0.8 1</diffuse>
      <specular>0.2 0.2 0.2 1</specular>
      <attenuation>
        <range>1000</range>
        <constant>0.9</constant>
        <linear>0.01</linear>
        <quadratic>0.001</quadratic>
      </attenuation>
      <direction>-0.5 0.1 -0.9</direction>
    </light>
    <model name='ground_plane'>
      <static>1</static>
      <link name='link'>
        <collision name='collision'>
          <geometry>
            <plane>
              <normal>0 0 1</normal>
              <size>100 100</size>
            </plane>
          </geometry>
          <surface>
            <friction>
              <ode>
                <mu>100</mu>
                <mu2>50</mu2>
              </ode>
              <torsional>
                <ode/>
              </torsional>
            </friction>
            <contact>
              <ode/>
            </contact>
            <bounce/>
          </surface>
          <max_contacts>10</max_contacts>
        </collision>
        <visual name='visual'>
          <cast_shadows>0</cast_shadows>
          <geometry>
            <plane>
              <normal>0 0 1</normal>
              <size>100 100</size>
            </plane>
          </geometry>
          <material>
            <script>
              <uri>file://media/materials/scripts/gazebo.material</uri>
              <name>Gazebo/Grey</name>
            </script>
          </material>
        </visual>
        <self_collide>0</self_collide>
        <enable_wind>0</enable_wind>
        <kinematic>0</kinematic>
      </link>
    </model>
    <gravity>0 0 -9.8</gravity>
    <magnetic_field>6e-06 2.3e-05 -4.2e-05</magnetic_field>
    <atmosphere type='adiabatic'/>
    <physics name='default_physics' default='0' type='ode'>
      <max_step_size>0.001</max_step_size>
      <real_time_factor>1</real_time_factor>
      <real_time_update_rate>1000</real_time_update_rate>
    </physics>
    <scene>
      <ambient>0.4 0.4 0.4 1</ambient>
      <background>0.7 0.7 0.7 1</background>
      <shadows>1</shadows>
    </scene>
    <wind/>
    <spherical_coordinates>
      <surface_model>EARTH_WGS84</surface_model>
      <latitude_deg>0</latitude_deg>
      <longitude_deg>0</longitude_deg>
      <elevation>0</elevation>
      <heading_deg>0</heading_deg>
    </spherical_coordinates>
    <model name='scouting_robot'>
      <link name='base_link'>
        <pose frame=''>0 0 0 0 -0 0</pose>
        <inertial>
          <pose frame=''>-0.2 0.00163 0.07094 0 -0 0</pose>
          <mass>1.5</mass>
          <inertia>
            <ixx>0.0025</ixx>
            <ixy>0.00013</ixy>
            <ixz>0.00419</ixz>
            <iyy>0.01593</iyy>
            <iyz>0</iyz>
            <izz>0.01605</izz>
          </inertia>
        </inertial>
        <collision name='base_link_collision'>
          <pose frame=''>0 0 0 0 -0 0</pose>
          <geometry>
            <mesh>
              <scale>1 1 1</scale>
              <uri>/home/juanes/catkin_ws/src/scouting_robot_description/meshes/body_front.dae</uri>
            </mesh>
          </geometry>
          <surface>
            <contact>
              <ode/>
            </contact>
            <friction>
              <ode/>
              <torsional>
                <ode/>
              </torsional>
            </friction>
            <bounce/>
          </surface>
          <max_contacts>10</max_contacts>
        </collision>
        <visual name='base_link_visual'>
          <pose frame=''>0 0 0 0 -0 0</pose>
          <geometry>
            <mesh>
              <scale>1 1 1</scale>
              <uri>/home/juanes/catkin_ws/src/scouting_robot_description/meshes/body_front.dae</uri>
            </mesh>
          </geometry>
          <material>
            <script>
              <uri>__default__</uri>
              <name>__default__</name>
            </script>
          </material>
        </visual>
        <gravity>1</gravity>
        <velocity_decay/>
        <self_collide>0</self_collide>
        <enable_wind>0</enable_wind>
        <kinematic>0</kinematic>
      </link>
      <link name='front_left_ankle'>
        <pose frame=''>0 0.085 -0.0015 0 -0 0</pose>
        <inertial>
          <pose frame=''>0 0.019 -0.0325 0 -0 0</pose>
          <mass>0.271</mass>
          <inertia>
            <ixx>0.01</ixx>
            <ixy>0</ixy>
            <ixz>0</ixz>
            <iyy>0.01</iyy>
            <iyz>0</iyz>
            <izz>0.01</izz>
          </inertia>
        </inertial>
        <collision name='front_left_ankle_collision'>
          <pose frame=''>0 0 0 0 -0 0</pose>
          <geometry>
            <mesh>
              <scale>1 1 1</scale>
              <uri>/home/juanes/catkin_ws/src/scouting_robot_description/meshes/hub.dae</uri>
            </mesh>
          </geometry>
          <surface>
            <contact>
              <ode/>
            </contact>
            <friction>
              <ode/>
              <torsional>
                <ode/>
              </torsional>
            </friction>
            <bounce/>
          </surface>
          <max_contacts>10</max_contacts>
        </collision>
        <visual name='front_left_ankle_visual'>
          <pose frame=''>0 0 0 0 -0 0</pose>
          <geometry>
            <mesh>
              <scale>1 1 1</scale>
              <uri>/home/juanes/catkin_ws/src/scouting_robot_description/meshes/hub.dae</uri>
            </mesh>
          </geometry>
          <material>
            <script>
              <uri>__default__</uri>
              <name>__default__</name>
            </script>
          </material>
        </visual>
        <gravity>1</gravity>
        <velocity_decay/>
        <self_collide>0</self_collide>
        <enable_wind>0</enable_wind>
        <kinematic>0</kinematic>
      </link>
      <joint name='front_left_steering_joint' type='revolute'>
        <child>front_left_ankle</child>
        <parent>base_link</parent>
        <axis>
          <xyz>0 0 1</xyz>
          <limit>
            <lower>-0.785398</lower>
            <upper>0.785398</upper>
            <effort>7</effort>
            <velocity>15</velocity>
          </limit>
          <dynamics>
            <spring_reference>0</spring_reference>
            <spring_stiffness>0</spring_stiffness>
          </dynamics>
          <use_parent_model_frame>1</use_parent_model_frame>
        </axis>
      </joint>
      <link name='front_left_wheel'>
        <pose frame=''>0 0.145 -0.0515 0 -0 0</pose>
        <inertial>
          <pose frame=''>0 0 0 1.5708 -0 0</pose>
          <mass>1.24</mass>
          <inertia>
            <ixx>0.00559808</ixx>
            <ixy>0</ixy>
            <ixz>0</ixz>
            <iyy>0.00559808</iyy>
            <iyz>0</iyz>
            <izz>0.0101835</izz>
          </inertia>
        </inertial>
        <collision name='front_left_wheel_collision'>
          <pose frame=''>0 0 0 1.5708 -0 0</pose>
          <geometry>
            <cylinder>
              <length>0.07</length>
              <radius>0.12</radius>
            </cylinder>
          </geometry>
          <surface>
            <contact>
              <ode/>
            </contact>
            <friction>
              <ode/>
              <torsional>
                <ode/>
              </torsional>
            </friction>
            <bounce/>
          </surface>
          <max_contacts>10</max_contacts>
        </collision>
        <visual name='front_left_wheel_visual'>
          <pose frame=''>0 0 0 0 -0 0</pose>
          <geometry>
            <mesh>
              <scale>1 1 1</scale>
              <uri>/home/juanes/catkin_ws/src/scouting_robot_description/meshes/l_wheel.dae</uri>
            </mesh>
          </geometry>
          <material>
            <script>
              <uri>__default__</uri>
              <name>__default__</name>
            </script>
          </material>
        </visual>
        <gravity>1</gravity>
        <velocity_decay/>
        <self_collide>0</self_collide>
        <enable_wind>0</enable_wind>
        <kinematic>0</kinematic>
      </link>
      <joint name='front_left_wheel_joint' type='revolute'>
        <child>front_left_wheel</child>
        <parent>front_left_ankle</parent>
        <axis>
          <xyz>0 1 0</xyz>
          <limit>
            <lower>-1e+16</lower>
            <upper>1e+16</upper>
          </limit>
          <dynamics>
            <spring_reference>0</spring_reference>
            <spring_stiffness>0</spring_stiffness>
          </dynamics>
          <use_parent_model_frame>1</use_parent_model_frame>
        </axis>
      </joint>
      <link name='front_right_ankle'>
        <pose frame=''>0 -0.085 -0.0015 0 -0 0</pose>
        <inertial>
          <pose frame=''>0 0.019 -0.0325 0 -0 0</pose>
          <mass>0.271</mass>
          <inertia>
            <ixx>0.01</ixx>
            <ixy>0</ixy>
            <ixz>0</ixz>
            <iyy>0.01</iyy>
            <iyz>0</iyz>
            <izz>0.01</izz>
          </inertia>
        </inertial>
        <collision name='front_right_ankle_collision'>
          <pose frame=''>0 0 0 0 -0 -3.14159</pose>
          <geometry>
            <mesh>
              <scale>1 1 1</scale>
              <uri>/home/juanes/catkin_ws/src/scouting_robot_description/meshes/hub.dae</uri>
            </mesh>
          </geometry>
          <surface>
            <contact>
              <ode/>
            </contact>
            <friction>
              <ode/>
              <torsional>
                <ode/>
              </torsional>
            </friction>
            <bounce/>
          </surface>
          <max_contacts>10</max_contacts>
        </collision>
        <visual name='front_right_ankle_visual'>
          <pose frame=''>0 0 0 0 -0 -3.14159</pose>
          <geometry>
            <mesh>
              <scale>1 1 1</scale>
              <uri>/home/juanes/catkin_ws/src/scouting_robot_description/meshes/hub.dae</uri>
            </mesh>
          </geometry>
          <material>
            <script>
              <uri>__default__</uri>
              <name>__default__</name>
            </script>
          </material>
        </visual>
        <gravity>1</gravity>
        <velocity_decay/>
        <self_collide>0</self_collide>
        <enable_wind>0</enable_wind>
        <kinematic>0</kinematic>
      </link>
      <joint name='front_right_steering_joint' type='revolute'>
        <child>front_right_ankle</child>
        <parent>base_link</parent>
        <axis>
          <xyz>0 0 1</xyz>
          <limit>
            <lower>-0.785398</lower>
            <upper>0.785398</upper>
            <effort>7</effort>
            <velocity>15</velocity>
          </limit>
          <dynamics>
            <spring_reference>0</spring_reference>
            <spring_stiffness>0</spring_stiffness>
          </dynamics>
          <use_parent_model_frame>1</use_parent_model_frame>
        </axis>
      </joint>
      <link name='front_right_wheel'>
        <pose frame=''>0 -0.145 -0.0515 0 -0 0</pose>
        <inertial>
          <pose frame=''>0 0 0 1.5708 -0 0</pose>
          <mass>1.24</mass>
          <inertia>
            <ixx>0.00559808</ixx>
            <ixy>0</ixy>
            <ixz>0</ixz>
            <iyy>0.00559808</iyy>
            <iyz>0</iyz>
            <izz>0.0101835</izz>
          </inertia>
        </inertial>
        <collision name='front_right_wheel_collision'>
          <pose frame=''>0 0 0 1.5708 -0 0</pose>
          <geometry>
            <cylinder>
              <length>0.07</length>
              <radius>0.12</radius>
            </cylinder>
          </geometry>
          <surface>
            <contact>
              <ode/>
            </contact>
            <friction>
              <ode/>
              <torsional>
                <ode/>
              </torsional>
            </friction>
            <bounce/>
          </surface>
          <max_contacts>10</max_contacts>
        </collision>
        <visual name='front_right_wheel_visual'>
          <pose frame=''>0 0 0 0 -0 -3.14159</pose>
          <geometry>
            <mesh>
              <scale>1 1 1</scale>
              <uri>/home/juanes/catkin_ws/src/scouting_robot_description/meshes/r_wheel.dae</uri>
            </mesh>
          </geometry>
          <material>
            <script>
              <uri>__default__</uri>
              <name>__default__</name>
            </script>
          </material>
        </visual>
        <gravity>1</gravity>
        <velocity_decay/>
        <self_collide>0</self_collide>
        <enable_wind>0</enable_wind>
        <kinematic>0</kinematic>
      </link>
      <joint name='front_right_wheel_joint' type='revolute'>
        <child>front_right_wheel</child>
        <parent>front_right_ankle</parent>
        <axis>
          <xyz>0 1 0</xyz>
          <limit>
            <lower>-1e+16</lower>
            <upper>1e+16</upper>
          </limit>
          <dynamics>
            <spring_reference>0</spring_reference>
            <spring_stiffness>0</spring_stiffness>
          </dynamics>
          <use_parent_model_frame>1</use_parent_model_frame>
        </axis>
      </joint>
      <link name='back_link'>
        <pose frame=''>-0.45 0 0 0 -0 0</pose>
        <inertial>
          <pose frame=''>0 -0.023 0.035 0 -0 0</pose>
          <mass>0.56</mass>
          <inertia>
            <ixx>0.000214</ixx>
            <ixy>0</ixy>
            <ixz>0</ixz>
            <iyy>0.0015171</iyy>
            <iyz>0</iyz>
            <izz>0.001316</izz>
          </inertia>
        </inertial>
        <collision name='back_link_collision'>
          <pose frame=''>0 0 0 0 -0 0</pose>
          <geometry>
            <mesh>
              <scale>1 1 1</scale>
              <uri>/home/juanes/catkin_ws/src/scouting_robot_description/meshes/body_back.dae</uri>
            </mesh>
          </geometry>
          <surface>
            <contact>
              <ode/>
            </contact>
            <friction>
              <ode/>
              <torsional>
                <ode/>
              </torsional>
            </friction>
            <bounce/>
          </surface>
          <max_contacts>10</max_contacts>
        </collision>
        <visual name='back_link_visual'>
          <pose frame=''>0 0 0 0 -0 0</pose>
          <geometry>
            <mesh>
              <scale>1 1 1</scale>
              <uri>/home/juanes/catkin_ws/src/scouting_robot_description/meshes/body_back.dae</uri>
            </mesh>
          </geometry>
          <material>
            <script>
              <uri>__default__</uri>
              <name>__default__</name>
            </script>
          </material>
        </visual>
        <gravity>1</gravity>
        <velocity_decay/>
        <self_collide>0</self_collide>
        <enable_wind>0</enable_wind>
        <kinematic>0</kinematic>
      </link>
      <joint name='pivot_joint' type='revolute'>
        <child>back_link</child>
        <parent>base_link</parent>
        <axis>
          <xyz>1 0 0</xyz>
          <limit>
            <lower>-0.785398</lower>
            <upper>0.785398</upper>
            <effort>10</effort>
            <velocity>5</velocity>
          </limit>
          <dynamics>
            <spring_reference>0</spring_reference>
            <spring_stiffness>0</spring_stiffness>
          </dynamics>
          <use_parent_model_frame>1</use_parent_model_frame>
        </axis>
      </joint>
      <link name='back_left_ankle'>
        <pose frame=''>-0.45 0.085 -0.0015 0 -0 0</pose>
        <inertial>
          <pose frame=''>0 0.019 -0.0325 0 -0 0</pose>
          <mass>0.271</mass>
          <inertia>
            <ixx>0.01</ixx>
            <ixy>0</ixy>
            <ixz>0</ixz>
            <iyy>0.01</iyy>
            <iyz>0</iyz>
            <izz>0.01</izz>
          </inertia>
        </inertial>
        <collision name='back_left_ankle_collision'>
          <pose frame=''>0 0 0 0 -0 0</pose>
          <geometry>
            <mesh>
              <scale>1 1 1</scale>
              <uri>/home/juanes/catkin_ws/src/scouting_robot_description/meshes/hub.dae</uri>
            </mesh>
          </geometry>
          <surface>
            <contact>
              <ode/>
            </contact>
            <friction>
              <ode/>
              <torsional>
                <ode/>
              </torsional>
            </friction>
            <bounce/>
          </surface>
          <max_contacts>10</max_contacts>
        </collision>
        <visual name='back_left_ankle_visual'>
          <pose frame=''>0 0 0 0 -0 0</pose>
          <geometry>
            <mesh>
              <scale>1 1 1</scale>
              <uri>/home/juanes/catkin_ws/src/scouting_robot_description/meshes/hub.dae</uri>
            </mesh>
          </geometry>
          <material>
            <script>
              <uri>__default__</uri>
              <name>__default__</name>
            </script>
          </material>
        </visual>
        <gravity>1</gravity>
        <velocity_decay/>
        <self_collide>0</self_collide>
        <enable_wind>0</enable_wind>
        <kinematic>0</kinematic>
      </link>
      <joint name='back_left_steering_joint' type='revolute'>
        <child>back_left_ankle</child>
        <parent>back_link</parent>
        <axis>
          <xyz>0 0 1</xyz>
          <limit>
            <lower>-0.785398</lower>
            <upper>0.785398</upper>
            <effort>7</effort>
            <velocity>15</velocity>
          </limit>
          <dynamics>
            <spring_reference>0</spring_reference>
            <spring_stiffness>0</spring_stiffness>
          </dynamics>
          <use_parent_model_frame>1</use_parent_model_frame>
        </axis>
      </joint>
      <link name='back_left_wheel'>
        <pose frame=''>-0.45 0.145 -0.0515 0 -0 0</pose>
        <inertial>
          <pose frame=''>0 0 0 1.5708 -0 0</pose>
          <mass>1.24</mass>
          <inertia>
            <ixx>0.00559808</ixx>
            <ixy>0</ixy>
            <ixz>0</ixz>
            <iyy>0.00559808</iyy>
            <iyz>0</iyz>
            <izz>0.0101835</izz>
          </inertia>
        </inertial>
        <collision name='back_left_wheel_collision'>
          <pose frame=''>0 0 0 1.5708 -0 0</pose>
          <geometry>
            <cylinder>
              <length>0.07</length>
              <radius>0.12</radius>
            </cylinder>
          </geometry>
          <surface>
            <contact>
              <ode/>
            </contact>
            <friction>
              <ode/>
              <torsional>
                <ode/>
              </torsional>
            </friction>
            <bounce/>
          </surface>
          <max_contacts>10</max_contacts>
        </collision>
        <visual name='back_left_wheel_visual'>
          <pose frame=''>0 0 0 0 -0 0</pose>
          <geometry>
            <mesh>
              <scale>1 1 1</scale>
              <uri>/home/juanes/catkin_ws/src/scouting_robot_description/meshes/l_wheel.dae</uri>
            </mesh>
          </geometry>
          <material>
            <script>
              <uri>__default__</uri>
              <name>__default__</name>
            </script>
          </material>
        </visual>
        <gravity>1</gravity>
        <velocity_decay/>
        <self_collide>0</self_collide>
        <enable_wind>0</enable_wind>
        <kinematic>0</kinematic>
      </link>
      <joint name='back_left_wheel_joint' type='revolute'>
        <child>back_left_wheel</child>
        <parent>back_left_ankle</parent>
        <axis>
          <xyz>0 1 0</xyz>
          <limit>
            <lower>-1e+16</lower>
            <upper>1e+16</upper>
          </limit>
          <dynamics>
            <spring_reference>0</spring_reference>
            <spring_stiffness>0</spring_stiffness>
          </dynamics>
          <use_parent_model_frame>1</use_parent_model_frame>
        </axis>
      </joint>
      <link name='back_right_ankle'>
        <pose frame=''>-0.45 -0.085 -0.0015 0 -0 0</pose>
        <inertial>
          <pose frame=''>0 0.019 -0.0325 0 -0 0</pose>
          <mass>0.271</mass>
          <inertia>
            <ixx>0.01</ixx>
            <ixy>0</ixy>
            <ixz>0</ixz>
            <iyy>0.01</iyy>
            <iyz>0</iyz>
            <izz>0.01</izz>
          </inertia>
        </inertial>
        <collision name='back_right_ankle_collision'>
          <pose frame=''>0 0 0 0 -0 -3.14159</pose>
          <geometry>
            <mesh>
              <scale>1 1 1</scale>
              <uri>/home/juanes/catkin_ws/src/scouting_robot_description/meshes/hub.dae</uri>
            </mesh>
          </geometry>
          <surface>
            <contact>
              <ode/>
            </contact>
            <friction>
              <ode/>
              <torsional>
                <ode/>
              </torsional>
            </friction>
            <bounce/>
          </surface>
          <max_contacts>10</max_contacts>
        </collision>
        <visual name='back_right_ankle_visual'>
          <pose frame=''>0 0 0 0 -0 -3.14159</pose>
          <geometry>
            <mesh>
              <scale>1 1 1</scale>
              <uri>/home/juanes/catkin_ws/src/scouting_robot_description/meshes/hub.dae</uri>
            </mesh>
          </geometry>
          <material>
            <script>
              <uri>__default__</uri>
              <name>__default__</name>
            </script>
          </material>
        </visual>
        <gravity>1</gravity>
        <velocity_decay/>
        <self_collide>0</self_collide>
        <enable_wind>0</enable_wind>
        <kinematic>0</kinematic>
      </link>
      <joint name='back_right_steering_joint' type='revolute'>
        <child>back_right_ankle</child>
        <parent>back_link</parent>
        <axis>
          <xyz>0 0 1</xyz>
          <limit>
            <lower>-0.785398</lower>
            <upper>0.785398</upper>
            <effort>7</effort>
            <velocity>15</velocity>
          </limit>
          <dynamics>
            <spring_reference>0</spring_reference>
            <spring_stiffness>0</spring_stiffness>
          </dynamics>
          <use_parent_model_frame>1</use_parent_model_frame>
        </axis>
      </joint>
      <link name='back_right_wheel'>
        <pose frame=''>-0.45 -0.145 -0.0515 0 -0 0</pose>
        <inertial>
          <pose frame=''>0 0 0 1.5708 -0 0</pose>
          <mass>1.24</mass>
          <inertia>
            <ixx>0.00559808</ixx>
            <ixy>0</ixy>
            <ixz>0</ixz>
            <iyy>0.00559808</iyy>
            <iyz>0</iyz>
            <izz>0.0101835</izz>
          </inertia>
        </inertial>
        <collision name='back_right_wheel_collision'>
          <pose frame=''>0 0 0 1.5708 -0 0</pose>
          <geometry>
            <cylinder>
              <length>0.07</length>
              <radius>0.12</radius>
            </cylinder>
          </geometry>
          <surface>
            <contact>
              <ode/>
            </contact>
            <friction>
              <ode/>
              <torsional>
                <ode/>
              </torsional>
            </friction>
            <bounce/>
          </surface>
          <max_contacts>10</max_contacts>
        </collision>
        <visual name='back_right_wheel_visual'>
          <pose frame=''>0 0 0 0 -0 -3.14159</pose>
          <geometry>
            <mesh>
              <scale>1 1 1</scale>
              <uri>/home/juanes/catkin_ws/src/scouting_robot_description/meshes/r_wheel.dae</uri>
            </mesh>
          </geometry>
          <material>
            <script>
              <uri>__default__</uri>
              <name>__default__</name>
            </script>
          </material>
        </visual>
        <gravity>1</gravity>
        <velocity_decay/>
        <self_collide>0</self_collide>
        <enable_wind>0</enable_wind>
        <kinematic>0</kinematic>
      </link>
      <joint name='back_right_wheel_joint' type='revolute'>
        <child>back_right_wheel</child>
        <parent>back_right_ankle</parent>
        <axis>
          <xyz>0 1 0</xyz>
          <limit>
            <lower>-1e+16</lower>
            <upper>1e+16</upper>
          </limit>
          <dynamics>
            <spring_reference>0</spring_reference>
            <spring_stiffness>0</spring_stiffness>
          </dynamics>
          <use_parent_model_frame>1</use_parent_model_frame>
        </axis>
      </joint>
      <static>0</static>
      <plugin name='gazebo_ros_control' filename='libgazebo_ros_control.so'>
        <robotNamespace>/scouting_robot</robotNamespace>
        <robotSimType>gazebo_ros_control/DefaultRobotHWSim</robotSimType>
      </plugin>
      <pose frame=''>0 0 1 0 -0 0</pose>
    </model>
    <light name='user_point_light_0' type='point'>
      <pose frame=''>-0.76188 1.2878 1 0 -0 0</pose>
      <diffuse>0.5 0.5 0.5 1</diffuse>
      <specular>0.1 0.1 0.1 1</specular>
      <attenuation>
        <range>20</range>
        <constant>0.5</constant>
        <linear>0.01</linear>
        <quadratic>0.001</quadratic>
      </attenuation>
      <cast_shadows>0</cast_shadows>
      <direction>0 0 -1</direction>
    </light>
    <light name='user_point_light_1' type='point'>
      <pose frame=''>0.102594 -1.10714 1 0 -0 0</pose>
      <diffuse>0.5 0.5 0.5 1</diffuse>
      <specular>0.1 0.1 0.1 1</specular>
      <attenuation>
        <range>20</range>
        <constant>0.5</constant>
        <linear>0.01</linear>
        <quadratic>0.001</quadratic>
      </attenuation>
      <cast_shadows>0</cast_shadows>
      <direction>0 0 -1</direction>
    </light>
    <state world_name='default'>
      <sim_time>159 773000000</sim_time>
      <real_time>160 431028626</real_time>
      <wall_time>1540925002 546822287</wall_time>
      <iterations>159773</iterations>
      <model name='ground_plane'>
        <pose frame=''>0 0 0 0 -0 0</pose>
        <scale>1 1 1</scale>
        <link name='link'>
          <pose frame=''>0 0 0 0 -0 0</pose>
          <velocity>0 0 0 0 -0 0</velocity>
          <acceleration>0 0 0 0 -0 0</acceleration>
          <wrench>0 0 0 0 -0 0</wrench>
        </link>
      </model>
      <model name='scouting_robot'>
        <pose frame=''>-0.051775 0.012971 0.1715 -5e-06 -1.6e-05 0.017432</pose>
        <scale>1 1 1</scale>
        <link name='back_left_ankle'>
          <pose frame=''>-0.503189 0.090117 0.169998 -6.4e-05 -4.8e-05 0.017456</pose>
          <velocity>-0.00195 0.000661 -0.007488 -0.005657 -0.010037 -0.001384</velocity>
          <acceleration>-1.61789 0.486325 -7.97148 -0.88707 -0.710469 -0.397837</acceleration>
          <wrench>-0.438448 0.131794 -2.16027 0 -0 0</wrench>
        </link>
        <link name='back_left_wheel'>
          <pose frame=''>-0.504234 0.150105 0.119995 -7.7e-05 -0.174634 0.017467</pose>
          <velocity>-0.001426 0.000444 -0.007825 -0.002575 -0.010005 -0.000761</velocity>
          <acceleration>-1.5871 0.418336 -7.99303 -2.50337 -0.680449 -0.603373</acceleration>
          <wrench>-1.96801 0.518736 -9.91136 0 -0 0</wrench>
        </link>
        <link name='back_link'>
          <pose frame=''>-0.501708 0.005127 0.171493 -9e-05 -1.1e-05 0.017434</pose>
          <velocity>-0.001825 -0.000172 -0.007414 -0.000112 -0.017877 0.000184</velocity>
          <acceleration>-1.68358 0.321307 -10.2459 1.63443 0.807035 -1.0305</acceleration>
          <wrench>-0.942803 0.179932 -5.73769 0 -0 0</wrench>
        </link>
        <link name='back_right_ankle'>
          <pose frame=''>-0.500226 -0.079859 0.169997 4.4e-05 -2.7e-05 0.017369</pose>
          <velocity>-0.001776 -0.000462 -0.00711 0.006938 -0.014951 0.001865</velocity>
          <acceleration>-1.18003 -0.294075 -8.35558 1.19517 0.756165 -1.24519</acceleration>
          <wrench>-0.319788 -0.079694 -2.26436 0 -0 0</wrench>
        </link>
        <link name='back_right_wheel'>
          <pose frame=''>-0.499182 -0.139846 0.119994 5.8e-05 -0.289867 0.017356</pose>
          <velocity>-0.001005 -0.000362 -0.007628 0.00481 -0.014966 0.001076</velocity>
          <acceleration>-0.660884 -0.01928 -7.92264 1.73032 1.11002 -3.13981</acceleration>
          <wrench>-0.819496 -0.023908 -9.82408 0 -0 0</wrench>
        </link>
        <link name='base_link'>
          <pose frame=''>-0.051775 0.012971 0.1715 -5e-06 -1.6e-05 0.017432</pose>
          <velocity>-0.002171 -0.000235 -0.000278 0.001489 -0.01546 0.000583</velocity>
          <acceleration>-1.87847 -0.052324 -9.06319 2.75358 -1.406 1.64846</acceleration>
          <wrench>-2.81771 -0.078485 -13.5948 0 -0 0</wrench>
        </link>
        <link name='front_left_ankle'>
          <pose frame=''>-0.053257 0.097958 0.17 -3e-06 -1.5e-05 0.017433</pose>
          <velocity>-0.002223 -0.000281 -8.5e-05 0.00201 -0.015193 0.000722</velocity>
          <acceleration>-0.951838 0.186504 -7.81951 1.1893 -1.42889 -1.81355</acceleration>
          <wrench>-0.257948 0.050542 -2.11909 0 -0 0</wrench>
        </link>
        <link name='front_left_wheel'>
          <pose frame=''>-0.054302 0.157949 0.12 -4e-06 0.011018 0.017433</pose>
          <velocity>-0.001579 -0.000192 1.5e-05 0.001626 -0.013692 0.001675</velocity>
          <acceleration>-0.872391 0.171195 -7.88304 -1.51387 -1.54275 1.94136</acceleration>
          <wrench>-1.08177 0.212282 -9.77497 0 -0 0</wrench>
        </link>
        <link name='front_right_ankle'>
          <pose frame=''>-0.050294 -0.072015 0.17 1e-06 -1.7e-05 0.017434</pose>
          <velocity>-0.002195 -0.00021 1.5e-05 -2.4e-05 -0.015233 -0.000275</velocity>
          <acceleration>-0.923509 -0.222096 -7.26866 -1.79172 -1.45864 3.05203</acceleration>
          <wrench>-0.250271 -0.060188 -1.96981 0 -0 0</wrench>
        </link>
        <link name='front_right_wheel'>
          <pose frame=''>-0.049247 -0.132006 0.12 1e-06 -0.069068 0.017435</pose>
          <velocity>-0.001545 -0.000178 4.5e-05 0.00147 -0.013445 -0.001781</velocity>
          <acceleration>-0.812763 -0.224754 -7.28249 1.75126 -1.0658 -1.36844</acceleration>
          <wrench>-1.00783 -0.278695 -9.03029 0 -0 0</wrench>
        </link>
      </model>
      <light name='sun'>
        <pose frame=''>0 0 10 0 -0 0</pose>
      </light>
      <light name='user_point_light_0'>
        <pose frame=''>-0.76188 1.2878 1 0 -0 0</pose>
      </light>
      <light name='user_point_light_1'>
        <pose frame=''>0.102594 -1.10714 1 0 -0 0</pose>
      </light>
    </state>
    <gui fullscreen='0'>
      <camera name='user_camera'>
        <pose frame=''>1.78275 -1.11848 0.927196 -0 0.363643 2.5882</pose>
        <view_controller>orbit</view_controller>
        <projection_type>perspective</projection_type>
      </camera>
    </gui>
  </world>
</sdf>
